Workbook

Sheet Hoja1
A1: SSNN FINAL | B1: DEPARTAMENTO | C1: TIPO | D1: DNI | E1: MES | F1: QVENTAS | G1: Urs | H1: ACELERADOR | I1: PLANILLA | J1: BONO | K1: CAMPAÑA | L1: OTROS | M1: PAGO TOTAL | N1: SS
A2: D&D | B2: ICA | C2: DESARROLLADOR | D2: 07339926 | E2: 202408 | F2: 305 | G2: 176 | H2: =IFERROR(VLOOKUP(Tabla1[[#This Row],[DNI]],Hoja3!B:G,2,0),0) -> 223 | I2: =IFERROR(VLOOKUP(Tabla1[[#This Row],[DNI]],Hoja3!B:G,3,0),0) -> 505 | J2: =IFERROR(VLOOKUP(Tabla1[[#This Row],[DNI]],Hoja3!B:G,4,0),0) -> 0 | K2: =0 -> 0 | L2: =IFERROR(VLOOKUP(Tabla1[[#This Row],[DNI]],Hoja3!B:G,5,0),0) -> 0 | M2: =IFERROR(VLOOKUP(Tabla1[[#This Row],[DNI]],Hoja3!B:G,6,0),0) -> 728 | N2: =IFERROR(VLOOKUP(Tabla1[[#This Row],[DNI]],Hoja2!A:C,3,0),0) -> 11
A3: GRUPO CAYAO | B3: LIMA | C3: DESARROLLADOR | D3: 45979464 | E3: 202408 | F3: 226 | G3: 57 | H3: =IFERROR(VLOOKUP(Tabla1[[#This Row],[DNI]],Hoja3!B:G,2,0),0) -> 780 | I3: =IFERROR(VLOOKUP(Tabla1[[#This Row],[DNI]],Hoja3!B:G,3,0),0) -> 1746 | J3: =IFERROR(VLOOKUP(Tabla1[[#This Row],[DNI]],Hoja3!B:G,4,0),0) -> 0 | K3: =0 -> 0 | L3: =IFERROR(VLOOKUP(Tabla1[[#This Row],[DNI]],Hoja3!B:G,5,0),0) -> 0 | M3: =IFERROR(VLOOKUP(Tabla1[[#This Row],[DNI]],Hoja3!B:G,6,0),0) -> 2526 | N3: =IFERROR(VLOOKUP(Tabla1[[#This Row],[DNI]],Hoja2!A:C,3,0),0) -> 14
A4: GRUPO CAYAO | B4: LIMA | C4: DESARROLLADOR | D4: 42193964 | E4: 202408 | F4: 423 | G4: 94 | H4: =IFERROR(VLOOKUP(Tabla1[[#This Row],[DNI]],Hoja3!B:G,2,0),0) -> 1685 | I4: =IFERROR(VLOOKUP(Tabla1[[#This Row],[DNI]],Hoja3!B:G,3,0),0) -> 2810 | J4: =IFERROR(VLOOKUP(Tabla1[[#This Row],[DNI]],Hoja3!B:G,4,0),0) -> 0 | K4: =0 -> 0 | L4: =IFERROR(VLOOKUP(Tabla1[[#This Row],[DNI]],Hoja3!B:G,5,0),0) -> 0 | M4: =IFERROR(VLOOKUP(Tabla1[[#This Row],[DNI]],Hoja3!B:G,6,0),0) -> 4495 | N4: =IFERROR(VLOOKUP(Tabla1[[#This Row],[DNI]],Hoja2!A:C,3,0),0) -> 22
A5: GRUPO CAYAO | B5: LIMA | C5: DESARROLLADOR | D5: 41783721 | E5: 202408 | F5: 317 | G5: 80 | H5: =IFERROR(VLOOKUP(Tabla1[[#This Row],[DNI]],Hoja3!B:G,2,0),0) -> 892 | I5: =IFERROR(VLOOKUP(Tabla1[[#This Row],[DNI]],Hoja3!B:G,3,0),0) -> 2428 | J5: =IFERROR(VLOOKUP(Tabla1[[#This Row],[DNI]],Hoja3!B:G,4,0),0) -> 0 | K5: =0 -> 0 | L5: =IFERROR(VLOOKUP(Tabla1[[#This Row],[DNI]],Hoja3!B:G,5,0),0) -> 0 | M5: =IFERROR(VLOOKUP(Tabla1[[#This Row],[DNI]],Hoja3!B:G,6,0),0) -> 3320 | N5: =IFERROR(VLOOKUP(Tabla1[[#This Row],[DNI]],Hoja2!A:C,3,0),0) -> 17
A6: PBD | B6: LIMA | C6: DESARROLLADOR | D6: 45096335 | E6: 202408 | F6: 198 | G6: 67 | H6: =IFERROR(VLOOKUP(Tabla1[[#This Row],[DNI]],Hoja3!B:G,2,0),0) -> 263 | I6: =IFERROR(VLOOKUP(Tabla1[[#This Row],[DNI]],Hoja3!B:G,3,0),0) -> 2006 | J6: =IFERROR(VLOOKUP(Tabla1[[#This Row],[DNI]],Hoja3!B:G,4,0),0) -> 0 | K6: =0 -> 0 | L6: =IFERROR(VLOOKUP(Tabla1[[#This Row],[DNI]],Hoja3!B:G,5,0),0) -> 0 | M6: =IFERROR(VLOOKUP(Tabla1[[#This Row],[DNI]],Hoja3!B:G,6,0),0) -> 2269 | N6: =IFERROR(VLOOKUP(Tabla1[[#This Row],[DNI]],Hoja2!A:C,3,0),0) -> 14
A7: GRUPO CAYAO | B7: CAJAMARCA | C7: DESARROLLADOR | D7: 73647869 | E7: 202408 | F7: 313 | G7: 97 | H7: =IFERROR(VLOOKUP(Tabla1[[#This Row],[DNI]],Hoja3!B:G,2,0),0) -> 700 | I7: =IFERROR(VLOOKUP(Tabla1[[#This Row],[DNI]],Hoja3!B:G,3,0),0) -> 4143 | J7: =IFERROR(VLOOKUP(Tabla1[[#This Row],[DNI]],Hoja3!B:G,4,0),0) -> 0 | K7: =0 -> 0 | L7: =IFERROR(VLOOKUP(Tabla1[[#This Row],[DNI]],Hoja3!B:G,5,0),0) -> 0 | M7: =IFERROR(VLOOKUP(Tabla1[[#This Row],[DNI]],Hoja3!B:G,6,0),0) -> 4843 | N7: =IFERROR(VLOOKUP(Tabla1[[#This Row],[DNI]],Hoja2!A:C,3,0),0) -> 31
A8: PBD | B8: LIMA | C8: DESARROLLADOR | D8: 002337284 | E8: 202408 | F8: 125 | G8: 53 | H8: =IFERROR(VLOOKUP(Tabla1[[#This Row],[DNI]],Hoja3!B:G,2,0),0) -> 47 | I8: =IFERROR(VLOOKUP(Tabla1[[#This Row],[DNI]],Hoja3!B:G,3,0),0) -> 885 | J8: =IFERROR(VLOOKUP(Tabla1[[#This Row],[DNI]],Hoja3!B:G,4,0),0) -> 0 | K8: =0 -> 0 | L8: =IFERROR(VLOOKUP(Tabla1[[#This Row],[DNI]],Hoja3!B:G,5,0),0) -> 0 | M8: =IFERROR(VLOOKUP(Tabla1[[#This Row],[DNI]],Hoja3!B:G,6,0),0) -> 932 | N8: =IFERROR(VLOOKUP(Tabla1[[#This Row],[DNI]],Hoja2!A:C,3,0),0) -> 6
A9: PBD | B9: LIMA | C9: DESARROLLADOR | D9: 44188901 | E9: 202408 | F9: 4 | G9: 1 | H9: =IFERROR(VLOOKUP(Tabla1[[#This Row],[DNI]],Hoja3!B:G,2,0),0) -> 0 | I9: =IFERROR(VLOOKUP(Tabla1[[#This Row],[DNI]],Hoja3!B:G,3,0),0) -> 100 | J9: =IFERROR(VLOOKUP(Tabla1[[#This Row],[DNI]],Hoja3!B:G,4,0),0) -> 0 | K9: =0 -> 0 | L9: =IFERROR(VLOOKUP(Tabla1[[#This Row],[DNI]],Hoja3!B:G,5,0),0) -> 0 | M9: =IFERROR(VLOOKUP(Tabla1[[#This Row],[DNI]],Hoja3!B:G,6,0),0) -> 100 | N9: =IFERROR(VLOOKUP(Tabla1[[#This Row],[DNI]],Hoja2!A:C,3,0),0) -> 0
A10: GRUPO CAYAO | B10: LIMA | C10: DESARROLLADOR | D10: 728656000 | E10: 202408 | F10: 88 | G10: 37 | H10: =IFERROR(VLOOKUP(Tabla1[[#This Row],[DNI]],Hoja3!B:G,2,0),0) -> 36 | I10: =IFERROR(VLOOKUP(Tabla1[[#This Row],[DNI]],Hoja3!B:G,3,0),0) -> 108 | J10: =IFERROR(VLOOKUP(Tabla1[[#This Row],[DNI]],Hoja3!B:G,4,0),0) -> 0 | K10: =0 -> 0 | L10: =IFERROR(VLOOKUP(Tabla1[[#This Row],[DNI]],Hoja3!B:G,5,0),0) -> 0 | M10: =IFERROR(VLOOKUP(Tabla1[[#This Row],[DNI]],Hoja3!B:G,6,0),0) -> 144 | N10: =IFERROR(VLOOKUP(Tabla1[[#This Row],[DNI]],Hoja2!A:C,3,0),0) -> 0
A11: GRUPO CAYAO | B11: LA LIBERTAD | C11: DESARROLLADOR | D11: 44589388 | E11: 202408 | F11: 370 | G11: 75 | H11: =IFERROR(VLOOKUP(Tabla1[[#This Row],[DNI]],Hoja3!B:G,2,0),0) -> 1252 | I11: =IFERROR(VLOOKUP(Tabla1[[#This Row],[DNI]],Hoja3!B:G,3,0),0) -> 2655 | J11: =IFERROR(VLOOKUP(Tabla1[[#This Row],[DNI]],Hoja3!B:G,4,0),0) -> 0 | K11: =0 -> 0 | L11: =IFERROR(VLOOKUP(Tabla1[[#This Row],[DNI]],Hoja3!B:G,5,0),0) -> 0 | M11: =IFERROR(VLOOKUP(Tabla1[[#This Row],[DNI]],Hoja3!B:G,6,0),0) -> 3907 | N11: =IFERROR(VLOOKUP(Tabla1[[#This Row],[DNI]],Hoja2!A:C,3,0),0) -> 14
A12: GRUPO CAYAO | B12: LIMA | C12: DESARROLLADOR | D12: 46332318 | E12: 202408 | F12: 21 | G12: 7 | H12: =IFERROR(VLOOKUP(Tabla1[[#This Row],[DNI]],Hoja3!B:G,2,0),0) -> 24 | I12: =IFERROR(VLOOKUP(Tabla1[[#This Row],[DNI]],Hoja3!B:G,3,0),0) -> 5 | J12: =IFERROR(VLOOKUP(Tabla1[[#This Row],[DNI]],Hoja3!B:G,4,0),0) -> 0 | K12: =0 -> 0 | L12: =IFERROR(VLOOKUP(Tabla1[[#This Row],[DNI]],Hoja3!B:G,5,0),0) -> 0 | M12: =IFERROR(VLOOKUP(Tabla1[[#This Row],[DNI]],Hoja3!B:G,6,0),0) -> 29 | N12: =IFERROR(VLOOKUP(Tabla1[[#This Row],[DNI]],Hoja2!A:C,3,0),0) -> 0
A13: FANERO | B13: HUANUCO | C13: DESARROLLADOR | D13: 41337882 | E13: 202408 | F13: 175 | G13: 34 | H13: =IFERROR(VLOOKUP(Tabla1[[#This Row],[DNI]],Hoja3!B:G,2,0),0) -> 180 | I13: =IFERROR(VLOOKUP(Tabla1[[#This Row],[DNI]],Hoja3!B:G,3,0),0) -> 1257 | J13: =IFERROR(VLOOKUP(Tabla1[[#This Row],[DNI]],Hoja3!B:G,4,0),0) -> 0 | K13: =0 -> 0 | L13: =IFERROR(VLOOKUP(Tabla1[[#This Row],[DNI]],Hoja3!B:G,5,0),0) -> 0 | M13: =IFERROR(VLOOKUP(Tabla1[[#This Row],[DNI]],Hoja3!B:G,6,0),0) -> 1437 | N13: =IFERROR(VLOOKUP(Tabla1[[#This Row],[DNI]],Hoja2!A:C,3,0),0) -> 8
... A1677: PBD | B1677: LIMA | C1677: HC EMO MERCADO | D1677: 77695986 | E1677: 202408 | F1677: 15 | G1677: 7 | H1677: =IFERROR(VLOOKUP(Tabla1[[#This Row],[DNI]],Hoja3!B:G,2,0),0) -> 0 | I1677: =IFERROR(VLOOKUP(Tabla1[[#This Row],[DNI]],Hoja3!B:G,3,0),0) -> 0 | J1677: =IFERROR(VLOOKUP(Tabla1[[#This Row],[DNI]],Hoja3!B:G,4,0),0) -> 0 | K1677: =0 -> 0 | L1677: =IFERROR(VLOOKUP(Tabla1[[#This Row],[DNI]],Hoja3!B:G,5,0),0) -> 0 | M1677: =IFERROR(VLOOKUP(Tabla1[[#This Row],[DNI]],Hoja3!B:G,6,0),0) -> 0 | N1677: =IFERROR(VLOOKUP(Tabla1[[#This Row],[DNI]],Hoja2!A:C,3,0),0) -> 0

Sheet Hoja3
A1: MEDIO | B1: (Varios elementos)
A2: PERIODO ACTIVIDAD | B2: 202408
A4: Suma de MONTO | C4: TIPO
A5: CANAL CORRECTO | B5: DNI | C5: ACELERADOR | D5: PLANILLA | E5: BONO | F5: CALIDAD | G5: Total general
A6: DAE | B6: 005211862 | C6: 3530 | D6: 4746 | E6: 0 | F6: 0 | G6: 8276
A7: DAE | B7: 005077995 | C7: 3532 | D7: 4686 | E7: 0 | F7: 0 | G7: 8218
A8: DAE | B8: 62002223 | C8: 2270 | D8: 3920 | E8: 0 | F8: 0 | G8: 6190
A9: DAE | B9: 41169937 | C9: 1818 | D9: 3801 | E9: 0 | F9: 0 | G9: 5619
A10: DAE | B10: 46053693 | C10: 1294 | D10: 4104 | E10: 0 | F10: 0 | G10: 5398
A11: DAE | B11: 003197405 | C11: 1428 | D11: 3761 | E11: 0 | F11: 0 | G11: 5189
A12: DAE | B12: 76159806 | C12: 927 | D12: 3792 | E12: 0 | F12: 0 | G12: 4719
A13: DAE | B13: 40098138 | C13: 1230 | D13: 3486 | E13: 0 | F13: 0 | G13: 4716
A14: DAE | B14: 76774313 | C14: 1715 | D14: 2974 | E14: 0 | F14: 0 | G14: 4689
A15: DAE | B15: 23989430 | C15: 500 | D15: 4140 | E15: 0 | F15: 0 | G15: 4640
A16: DAE | B16: 46533458 | C16: 1385 | D16: 3170 | E16: 0 | F16: 0 | G16: 4555
A17: DAE | B17: 47428279 | C17: 755 | D17: 3747 | E17: 0 | F17: 0 | G17: 4502
... A381: DAE | B381: 001308316 | C381: 50 | D381: 220 | E381: 0 | F381: 0 | G381: 270
A382: DAE | B382: 40587485 | C382: 0 | D382: 268 | E382: 0 | F382: 0 | G382: 268
A383: DAE | B383: 025669543 | C383: 55 | D383: 209 | E383: 0 | F383: 0 | G383: 264
A384: DAE | B384: 76516043 | C384: 50 | D384: 209 | E384: 0 | F384: 0 | G384: 259
A385: DAE | B385: 00120406 | C385: 90 | D385: 160 | E385: 0 | F385: 0 | G385: 250
A386: DAE | B386: 75064228 | C386: 20 | D386: 215 | E386: 0 | F386: 0 | G386: 235
A387: DAE | B387: 76243488 | C387: 60 | D387: 170 | E387: 0 | F387: 0 | G387: 230
A388: DAE | B388: 74414818 | C388: 80 | D388: 150 | E388: 0 | F388: 0 | G388: 230
A389: DAE | B389: 44005119 | C389: 140 | D389: 88 | E389: 0 | F389: 0 | G389: 228
A390: DAE | B390: 42256544 | C390: 222 | D390: 0 | E390: 0 | F390: 0 | G390: 222
A391: DAE | B391: 41190222 | C391: 0 | D391: 218 | E391: 0 | F391: 0 | G391: 218
A392: DAE | B392: 43939018 | C392: 0 | D392: 215 | E392: 0 | F392: 0 | G392: 215
A393: DAE | B393: 75672961 | C393: 0 | D393: 210 | E393: 0 | F393: 0 | G393: 210
A394: DAE | B394: 44854927 | C394: 50 | D394: 160 | E394: 0 | F394: 0 | G394: 210
... A488: DAE | B488: 80078619 | C488: 0 | D488: 50 | E488: 0 | F488: 0 | G488: 50
A489: DAE | B489: 73425975 | C489: 50 | D489: 0 | E489: 0 | F489: 0 | G489: 50
A490: DAE | B490: 44986566 | C490: 50 | D490: 0 | E490: 0 | F490: 0 | G490: 50
A491: DAE | B491: 000921136 | C491: 50 | D491: 0 | E491: 0 | F491: 0 | G491: 50
A492: DAE | B492: 45715098 | C492: 0 | D492: 50 | E492: 0 | F492: 0 | G492: 50
A493: DAE | B493: 03682196 | C493: 0 | D493: 50 | E493: 0 | F493: 0 | G493: 50
A494: DAE | B494: 46251296 | C494: 0 | D494: 48 | E494: 0 | F494: 0 | G494: 48
A495: DAE | B495: 70230196 | C495: 0 | D495: 40 | E495: 0 | F495: 0 | G495: 40
A496: DAE | B496: 74978767 | C496: 20 | D496: 20 | E496: 0 | F496: 0 | G496: 40
A497: DAE | B497: 76936225 | C497: 0 | D497: 40 | E497: 0 | F497: 0 | G497: 40
...

Sheet Hoja2
A1: LOGIN | B1: TIPO FINAL | C1: Suma de SS
A2: 000010940 | B2: PDV | C2: 0
A3: 000056828 | B3: FULL PREPAGO DAE | C3: 0
A4: 000065472 | B4: PDV | C4: 0
A5: 000096588 | B5: PDV | C5: 0
A6: 000136699 | B6: PDV | C6: 0
A7: 000138455 | B7: PDV | C7: 0
A8: 000149452 | B8: FULL PREPAGO DAE | C8: 0
A9: 000159738 | B9: PDV | C9: 0
A10: 000204444 | B10: PDV | C10: 2
A11: 000212751 | B11: PDV | C11: 0
A12: 000237276 | B12: DAE | C12: 10
A13: 000303722 | B13: PDV | C13: 0
... A11086: 91690730 | B11086: FULL PREPAGO DAE | C11086: 0
