Workbook

Sheet Hoja1
A1: SSNN FINAL | B1: DEPARTAMENTO | C1: TIPO | D1: DNI | E1: MES | F1: QVENTAS | G1: Urs | H1: ACELERADOR | I1: PLANILLA | J1: BONO | K1: CAMPAÑA | L1: OTROS | M1: PAGO TOTAL | N1: SS
A2: PBD | B2: LIMA | C2: DESARROLLADOR | D2: 76780824 | E2: 202409 | F2: 42 | G2: 23 | H2: =IFERROR(VLOOKUP(D2,Hoja2!B:H,2,0),0) -> 20 | I2: =IFERROR(VLOOKUP(D2,Hoja2!B:H,3,0),0) -> 0 | J2: =IFERROR(VLOOKUP(D2,Hoja2!B:H,4,0),0) -> 0 | K2: =IFERROR(VLOOKUP(D2,Hoja2!B:H,5,0),0) -> 0 | L2: =0 -> 0 | M2: =IFERROR(VLOOKUP(D2,Hoja2!B:H,6,0),0) -> 20 | N2: =VLOOKUP(Tabla1[[#This Row],[DNI]],[1]Export!$A:$B,2,0) -> 2
A3: PBD | B3: LIMA | C3: DESARROLLADOR | D3: 45840759 | E3: 202409 | F3: 231 | G3: 109 | H3: =IFERROR(VLOOKUP(D3,Hoja2!B:H,2,0),0) -> 0 | I3: =IFERROR(VLOOKUP(D3,Hoja2!B:H,3,0),0) -> 1759 | J3: =IFERROR(VLOOKUP(D3,Hoja2!B:H,4,0),0) -> 0 | K3: =IFERROR(VLOOKUP(D3,Hoja2!B:H,5,0),0) -> 0 | L3: =0 -> 0 | M3: =IFERROR(VLOOKUP(D3,Hoja2!B:H,6,0),0) -> 1759 | N3: =VLOOKUP(Tabla1[[#This Row],[DNI]],[1]Export!$A:$B,2,0) -> 14
A4: PBD | B4: LIMA | C4: DESARROLLADOR | D4: 80311788 | E4: 202409 | F4: 279 | G4: 138 | H4: =IFERROR(VLOOKUP(D4,Hoja2!B:H,2,0),0) -> 144 | I4: =IFERROR(VLOOKUP(D4,Hoja2!B:H,3,0),0) -> 0 | J4: =IFERROR(VLOOKUP(D4,Hoja2!B:H,4,0),0) -> 0 | K4: =IFERROR(VLOOKUP(D4,Hoja2!B:H,5,0),0) -> 0 | L4: =0 -> 0 | M4: =IFERROR(VLOOKUP(D4,Hoja2!B:H,6,0),0) -> 144 | N4: =VLOOKUP(Tabla1[[#This Row],[DNI]],[1]Export!$A:$B,2,0) -> 9
A5: GRUPO CAYAO | B5: LIMA | C5: DESARROLLADOR | D5: 45979464 | E5: 202409 | F5: 323 | G5: 82 | H5: =IFERROR(VLOOKUP(D5,Hoja2!B:H,2,0),0) -> 460 | I5: =IFERROR(VLOOKUP(D5,Hoja2!B:H,3,0),0) -> 0 | J5: =IFERROR(VLOOKUP(D5,Hoja2!B:H,4,0),0) -> 0 | K5: =IFERROR(VLOOKUP(D5,Hoja2!B:H,5,0),0) -> 0 | L5: =0 -> 0 | M5: =IFERROR(VLOOKUP(D5,Hoja2!B:H,6,0),0) -> 460 | N5: =VLOOKUP(Tabla1[[#This Row],[DNI]],[1]Export!$A:$B,2,0) -> 18
A6: GRUPO CAYAO | B6: LIMA | C6: DESARROLLADOR | D6: 42193964 | E6: 202409 | F6: 376 | G6: 91 | H6: =IFERROR(VLOOKUP(D6,Hoja2!B:H,2,0),0) -> 681 | I6: =IFERROR(VLOOKUP(D6,Hoja2!B:H,3,0),0) -> 0 | J6: =IFERROR(VLOOKUP(D6,Hoja2!B:H,4,0),0) -> 0 | K6: =IFERROR(VLOOKUP(D6,Hoja2!B:H,5,0),0) -> 0 | L6: =0 -> 0 | M6: =IFERROR(VLOOKUP(D6,Hoja2!B:H,6,0),0) -> 681 | N6: =VLOOKUP(Tabla1[[#This Row],[DNI]],[1]Export!$A:$B,2,0) -> 21
A7: GRUPO CAYAO | B7: LIMA | C7: DESARROLLADOR | D7: 41783721 | E7: 202409 | F7: 354 | G7: 75 | H7: =IFERROR(VLOOKUP(D7,Hoja2!B:H,2,0),0) -> 520 | I7: =IFERROR(VLOOKUP(D7,Hoja2!B:H,3,0),0) -> 0 | J7: =IFERROR(VLOOKUP(D7,Hoja2!B:H,4,0),0) -> 0 | K7: =IFERROR(VLOOKUP(D7,Hoja2!B:H,5,0),0) -> 0 | L7: =0 -> 0 | M7: =IFERROR(VLOOKUP(D7,Hoja2!B:H,6,0),0) -> 520 | N7: =VLOOKUP(Tabla1[[#This Row],[DNI]],[1]Export!$A:$B,2,0) -> 20
A8: PBD | B8: LIMA | C8: DESARROLLADOR | D8: 45096335 | E8: 202409 | F8: 191 | G8: 79 | H8: =IFERROR(VLOOKUP(D8,Hoja2!B:H,2,0),0) -> 0 | I8: =IFERROR(VLOOKUP(D8,Hoja2!B:H,3,0),0) -> 1482 | J8: =IFERROR(VLOOKUP(D8,Hoja2!B:H,4,0),0) -> 0 | K8: =IFERROR(VLOOKUP(D8,Hoja2!B:H,5,0),0) -> 0 | L8: =0 -> 0 | M8: =IFERROR(VLOOKUP(D8,Hoja2!B:H,6,0),0) -> 1482 | N8: =VLOOKUP(Tabla1[[#This Row],[DNI]],[1]Export!$A:$B,2,0) -> 13
A9: GRUPO CAYAO | B9: CAJAMARCA | C9: DESARROLLADOR | D9: 73647869 | E9: 202409 | F9: 313 | G9: 91 | H9: =IFERROR(VLOOKUP(D9,Hoja2!B:H,2,0),0) -> 180 | I9: =IFERROR(VLOOKUP(D9,Hoja2!B:H,3,0),0) -> 0 | J9: =IFERROR(VLOOKUP(D9,Hoja2!B:H,4,0),0) -> 0 | K9: =IFERROR(VLOOKUP(D9,Hoja2!B:H,5,0),0) -> 0 | L9: =0 -> 0 | M9: =IFERROR(VLOOKUP(D9,Hoja2!B:H,6,0),0) -> 180 | N9: =VLOOKUP(Tabla1[[#This Row],[DNI]],[1]Export!$A:$B,2,0) -> 25
A10: PBD | B10: LIMA | C10: DESARROLLADOR | D10: 136017280 | E10: 202409 | F10: 166 | G10: 51 | H10: =IFERROR(VLOOKUP(D10,Hoja2!B:H,2,0),0) -> 240 | I10: =IFERROR(VLOOKUP(D10,Hoja2!B:H,3,0),0) -> 0 | J10: =IFERROR(VLOOKUP(D10,Hoja2!B:H,4,0),0) -> 0 | K10: =IFERROR(VLOOKUP(D10,Hoja2!B:H,5,0),0) -> 0 | L10: =0 -> 0 | M10: =IFERROR(VLOOKUP(D10,Hoja2!B:H,6,0),0) -> 240 | N10: =VLOOKUP(Tabla1[[#This Row],[DNI]],[1]Export!$A:$B,2,0) -> 8
A11: PBD | B11: LIMA | C11: DESARROLLADOR | D11: 002337284 | E11: 202409 | F11: 127 | G11: 47 | H11: =IFERROR(VLOOKUP(D11,Hoja2!B:H,2,0),0) -> 60 | I11: =IFERROR(VLOOKUP(D11,Hoja2!B:H,3,0),0) -> 0 | J11: =IFERROR(VLOOKUP(D11,Hoja2!B:H,4,0),0) -> 0 | K11: =IFERROR(VLOOKUP(D11,Hoja2!B:H,5,0),0) -> 0 | L11: =0 -> 0 | M11: =IFERROR(VLOOKUP(D11,Hoja2!B:H,6,0),0) -> 60 | N11: =VLOOKUP(Tabla1[[#This Row],[DNI]],[1]Export!$A:$B,2,0) -> 9
A12: PBD | B12: LIMA | C12: DESARROLLADOR | D12: 44188901 | E12: 202409 | F12: 2 | G12: 0 | H12: =IFERROR(VLOOKUP(D12,Hoja2!B:H,2,0),0) -> 0 | I12: =IFERROR(VLOOKUP(D12,Hoja2!B:H,3,0),0) -> 5 | J12: =IFERROR(VLOOKUP(D12,Hoja2!B:H,4,0),0) -> 0 | K12: =IFERROR(VLOOKUP(D12,Hoja2!B:H,5,0),0) -> 0 | L12: =0 -> 0 | M12: =IFERROR(VLOOKUP(D12,Hoja2!B:H,6,0),0) -> 5 | N12: =VLOOKUP(Tabla1[[#This Row],[DNI]],[1]Export!$A:$B,2,0) -> 0
A13: GRUPO CAYAO | B13: LIMA | C13: DESARROLLADOR | D13: 728656000 | E13: 202409 | F13: 95 | G13: 45 | H13: =IFERROR(VLOOKUP(D13,Hoja2!B:H,2,0),0) -> 40 | I13: =IFERROR(VLOOKUP(D13,Hoja2!B:H,3,0),0) -> 0 | J13: =IFERROR(VLOOKUP(D13,Hoja2!B:H,4,0),0) -> 0 | K13: =IFERROR(VLOOKUP(D13,Hoja2!B:H,5,0),0) -> 0 | L13: =0 -> 0 | M13: =IFERROR(VLOOKUP(D13,Hoja2!B:H,6,0),0) -> 40 | N13: =VLOOKUP(Tabla1[[#This Row],[DNI]],[1]Export!$A:$B,2,0) -> 3
... A1613: TVOLUTION | B1613: CUSCO | C1613: DESARROLLADOR | D1613: 42482636 | E1613: 202409 | F1613: 5 | G1613: 3 | H1613: =IFERROR(VLOOKUP(D1613,Hoja2!B:H,2,0),0) -> 0 | I1613: =IFERROR(VLOOKUP(D1613,Hoja2!B:H,3,0),0) -> 0 | J1613: =IFERROR(VLOOKUP(D1613,Hoja2!B:H,4,0),0) -> 0 | K1613: =IFERROR(VLOOKUP(D1613,Hoja2!B:H,5,0),0) -> 0 | L1613: =0 -> 0 | M1613: =IFERROR(VLOOKUP(D1613,Hoja2!B:H,6,0),0) -> 0 | N1613: =VLOOKUP(Tabla1[[#This Row],[DNI]],[1]Export!$A:$B,2,0) -> #N/A

Sheet Hoja2
A1: MEDIO | B1: (Varios elementos)
A2: PERIODO ACTIVIDAD | B2: 202409
A4: Suma de MONTO
A5: TIPO - CANAL | B5: DNI | C5: ACELERADOR | D5: PLANILLA | E5: BONO | F5: CAMPAÑA | G5: Total general
A6: DAE | B6: 2818076 | C6: 40 | D6: 0 | E6: 0 | F6: 0 | G6: 40
A7: DAE | B7: 3682196 | C7: 40 | D7: 0 | E7: 0 | F7: 0 | G7: 40
A8: DAE | B8: 5336035 | C8: 52 | D8: 0 | E8: 0 | F8: 0 | G8: 52
A9: DAE | B9: 10638291 | C9: 52 | D9: 0 | E9: 0 | F9: 0 | G9: 52
A10: DAE | B10: 16774320 | C10: 52 | D10: 0 | E10: 0 | F10: 0 | G10: 52
A11: DAE | B11: 24772669 | C11: 80 | D11: 0 | E11: 0 | F11: 0 | G11: 80
A12: DAE | B12: 40386832 | C12: 40 | D12: 0 | E12: 0 | F12: 0 | G12: 40
A13: DAE | B13: 41489015 | C13: 52 | D13: 0 | E13: 0 | F13: 0 | G13: 52
A14: DAE | B14: 41772284 | C14: 52 | D14: 0 | E14: 0 | F14: 0 | G14: 52
A15: DAE | B15: 41863329 | C15: 40 | D15: 0 | E15: 0 | F15: 0 | G15: 40
A16: DAE | B16: 43245119 | C16: 40 | D16: 0 | E16: 0 | F16: 0 | G16: 40
A17: DAE | B17: 43447567 | C17: 70 | D17: 0 | E17: 0 | F17: 0 | G17: 70
... A86: DAE | B86: 80109136 | C86: 52 | D86: 0 | E86: 0 | F86: 0 | G86: 52
A87: DAE | B87: 000237276 | C87: 594 | D87: 1419 | E87: 0 | F87: 0 | G87: 2013
A88: DAE | B88: 000409961 | C88: 780 | D88: 1766 | E88: 0 | F88: 0 | G88: 2546
A89: DAE | B89: 000622795 | C89: 0 | D89: 0 | E89: 0 | F89: 72 | G89: 72
A90: DAE | B90: 000921136 | C90: 108 | D90: 0 | E90: 0 | F90: 0 | G90: 108
A91: DAE | B91: 000957881 | C91: 0 | D91: 2610 | E91: 0 | F91: 0 | G91: 2610
A92: DAE | B92: 001166265 | C92: 0 | D92: 765 | E92: 0 | F92: 0 | G92: 765
A93: DAE | B93: 00120406 | C93: 20 | D93: 265 | E93: 0 | F93: 0 | G93: 285
A94: DAE | B94: 001215616 | C94: 0 | D94: 60 | E94: 0 | F94: 0 | G94: 60
A95: DAE | B95: 001308316 | C95: 0 | D95: 50 | E95: 0 | F95: 0 | G95: 50
A96: DAE | B96: 001523250 | C96: 0 | D96: 94 | E96: 0 | F96: 66 | G96: 160
A97: DAE | B97: 001756972 | C97: 1108 | D97: 2370 | E97: 0 | F97: 0 | G97: 3478
A98: DAE | B98: 001761361 | C98: 405 | D98: 275 | E98: 0 | F98: 0 | G98: 680
... A727: DESARROLLADOR | B727: 80311788 | C727: 0 | D727: 520 | E727: 0 | F727: 0 | G727: 520
A728: DESARROLLADOR E2 | B728: 41337882 | C728: 52 | D728: 0 | E728: 0 | F728: 0 | G728: 52
A729: DESARROLLADOR E2 | B729: 45096335 | C729: 63 | D729: 0 | E729: 0 | F729: 0 | G729: 63
A730: DESARROLLADOR E2 | B730: 45979464 | C730: 63 | D730: 0 | E730: 0 | F730: 0 | G730: 63
A731: DESARROLLADOR E2 | B731: 60730674 | C731: 52 | D731: 0 | E731: 0 | F731: 0 | G731: 52
A732: DESARROLLADOR E2 | B732: 61876416 | C732: 40 | D732: 0 | E732: 0 | F732: 0 | G732: 40
A733: DESARROLLADOR E2 | B733: 70030505 | C733: 63 | D733: 0 | E733: 0 | F733: 0 | G733: 63
A734: DESARROLLADOR E2 | B734: 77124724 | C734: 52 | D734: 0 | E734: 0 | F734: 0 | G734: 52
A735: DESARROLLADOR E2 | B735: 80311788 | C735: 40 | D735: 0 | E735: 0 | F735: 0 | G735: 40
A736: DESARROLLADOR E2 | B736: 001756174 | C736: 236 | D736: 0 | E736: 0 | F736: 0 | G736: 236
A737: DESARROLLADOR E2 | B737: 002263787 | C737: 533 | D737: 0 | E737: 0 | F737: 0 | G737: 533
...
